<?xml version="1.0"?>
<robot xmlns:xacro="http://www.ros.org/wiki/xacro">
    <xacro:include filename="inertial_macros.xacro"/>
    <material name="white">
        <color rgba="1 1 1 1"/>
    </material>
    <material name="black">
        <color rgba="0 0 0 1"/>
    </material>
    <material name="red">
        <color rgba="1 0 0 1"/>
    </material>
    <material name="green">
        <color rgba="0 1 0 1"/>
    </material>
    <material name="blue">
        <color rgba="0 0 1 1"/>
    </material>
    <!-- Tạo ra một link có tên là base_link; đây sẽ là link gốc của robot -->

    <link name="base_link">

    </link>
    <!-- Tạo ra một joint cố định giữa base_link và chassis -->
    <joint name="chassis_joint" type="fixed"> 
        <parent link="base_link"/>
        <child link="chassis"/>
        <origin xyz="-0.1 0 0" rpy="0 0 0"/> 
    </joint>
    <!-- Tạo ra một link có tên là khung xe; link này sẽ là con của base_link -->
    <link name="chassis">
        <!-- Visual (hình ảnh) -->
        <visual>
            <origin xyz="0.15 0 0.075"/>
            <geometry>
                <box size="0.3 0.3 0.15"/>
            </geometry>
            <material name="white"/>
        </visual>
    <collision>
            <origin xyz="0.15 0 0.075"/>
            <geometry>
                <box size="0.3 0.3 0.15"/>
            </geometry>
    </collision>
    <xacro:inertial_box mass="0.5" x="0.3" y="0.3" z="0.15">
        <origin xyz="0.15 0 0.075" rpy="0 0 0"/>
    </xacro:inertial_box>
    </link>
    <gazebo refercence="chassis">
        <material >Gazebo/White</material>
    </gazebo>

    <!-- Tạo ra một joint có tên là left_wheel_joint; joint này kết nối base_link với left_wheel -->
    <joint name="left_wheel_joint" type="continuous">
        <parent link="base_link"/>
        <child link="left_wheel"/>
        <origin xyz="0 0.175 0" rpy="-${pi/2} 0 0"/>
        <axis xyz="0 0 1"/>
    </joint>
    <link name = "left_wheel">
        <visual>
            <geometry>
                <cylinder radius="0.05" length="0.04"/>
            </geometry>
            <material name="blue"/>
        </visual>
    <collision>
            <geometry>
                <cylinder radius="0.05" length="0.04"/>
            </geometry>
        </collision>
        <xacro:inertial_cylinder mass="0.1" length="0.04" radius="0.05">
          <origin xyz="0 0 0" rpy="0 0 0"/>
    </xacro:inertial_cylinder>
    </link>
      <gazebo refercence="left_wheel">
        <material >Gazebo/Blue</material>
    </gazebo>
    
    <!-- Tạo ra một joint có tên là right_wheel_joint; joint này kết nối base_link với right_wheel -->
    <joint name="right_wheel_joint" type="continuous">
        <parent link="base_link"/>
        <child link="right_wheel"/>
        <origin xyz="0 -0.175 0" rpy="${pi/2} 0 0"/>
        <axis xyz="0 0 -1"/>
    </joint>
    <link name = "right_wheel">
        <visual>
            <geometry>
                <cylinder radius="0.05" length="0.04"/>
            </geometry>
            <material name="blue"/>
        </visual>
        <collision>
            <geometry>
                <cylinder radius="0.05" length="0.04"/>
            </geometry>
        </collision>
    <xacro:inertial_cylinder mass="0.1" length="0.04" radius="0.05">
          <origin xyz="0 0 0" rpy="0 0 0"/>
    </xacro:inertial_cylinder>
    </link>
      <gazebo refercence="right_wheel">
        <material >Gazebo/Blue</material>
    </gazebo>

    <!-- caster_wheel -->
    <joint name="caster_wheel_joint" type="fixed">
        <parent link="chassis"/>
        <child link="caster_wheel"/>
        <origin xyz="0.24 0 0"/>
    </joint>
    <link name="caster_wheel">
        <visual>
            <geometry>
                <sphere radius="0.05"/>
            </geometry>
            <material name="black"/>
        </visual>
        <collision>
            <geometry>
                <sphere radius="0.05"/>
            </geometry>
        </collision>
    <xacro:inertial_sphere mass="0.1" radius="0.05">
            <origin xyz="0 0 0" rpy="0 0 0"/>
    </xacro:inertial_sphere>
    </link>
    <gazebo refercence="caster_wheel">
        <material >Gazebo/Black</material>
    </gazebo>
</robot>